<?xml version="1.0" encoding="utf-8"?>
<!-- This URDF was automatically created by SolidWorks to URDF Exporter! Originally created by Stephen Brawner (brawner@gmail.com) 
     Commit Version: 1.6.0-4-g7f85cfe  Build Version: 1.6.7995.38578
     For more information, please see http://wiki.ros.org/sw_urdf_exporter -->
<robot
  name="bi_urdf">
  <link name="dummy_link"/>  
  <joint name="dummy_joint" type="floating">
    <parent link="dummy_link"/>
    <child link="base_link"/>
    <origin xyz="0 0 0" rpy="0 0 0"/>
  </joint>
  <link
    name="base_link">
    <inertial>
      <origin
        xyz="0.01096 0.00049 -0.08447"
        rpy="0 0 0" />
      <mass
        value="1.7" />
      <inertia
        ixx="0.01982751490"
        ixy="-0.00000294181"
        ixz="-0.00095254067"
        iyy="0.02421281189"
        iyz="-0.00012740135"
        izz="0.01088542480" />
    </inertial>
    <visual>
      <origin
        xyz="0 0 0"
        rpy="0 0 0" />
      <geometry>
        <mesh
          filename="package://bi_urdf/meshes/base_link.STL" />
      </geometry>
      <material
        name="">
        <color
          rgba="1 0 0 1" />
      </material>
    </visual>
    <collision>
      <origin
        xyz="0 0 0"
        rpy="0 0 0" />
      <geometry>
        <mesh
          filename="package://bi_urdf/meshes/base_link.STL" />
      </geometry>
    </collision>
  </link>
  <link
    name="orin_Link">
    <inertial>
      <origin
        xyz="-0.02408 0.02189 0.05730"
        rpy="0 0 0" />
      <mass
        value="0.3" />
      <inertia
        ixx="0.00169870356"
        ixy="-0.00015111217"
        ixz="-0.00041542219"
        iyy="0.00147844807"
        iyz="0.00038916625"
        izz="0.00065122384" />
    </inertial>
    <visual>
      <origin
        xyz="0 0 0"
        rpy="0 0 0" />
      <geometry>
        <mesh
          filename="package://bi_urdf/meshes/orin_Link.STL" />
      </geometry>
      <material
        name="">
        <color
          rgba="0.2 0.2 0.2 1" />
      </material>
    </visual>
    <collision>
      <origin
        xyz="0 0 0"
        rpy="0 0 0" />
      <geometry>
        <mesh
          filename="package://bi_urdf/meshes/orin_Link.STL" />
      </geometry>
    </collision>
  </link>
  <joint
    name="orin"
    type="continuous">
    <origin
      xyz="-0.0918148109842786 -0.0249000000000198 -0.117725"
      rpy="0 0 0" />
    <parent
      link="base_link" />
    <child
      link="orin_Link" />
    <axis
      xyz="1 0 0" />
  </joint>
  <link
    name="bat_Link">
    <inertial>
      <origin
        xyz="0.02860 0.00224 0.02251"
        rpy="0 0 0" />
      <mass
        value="0.672" />
      <inertia
        ixx="0.00085048156"
        ixy="-0.00001152336"
        ixz="0.00043231469"
        iyy="0.00203345215"
        iyz="0.00003388068"
        izz="0.00199728964"/>
    </inertial>
    <visual>
      <origin
        xyz="0 0 0"
        rpy="0 0 0" />
      <geometry>
        <mesh
          filename="package://bi_urdf/meshes/bat_Link.STL" />
      </geometry>
      <material
        name="">
        <color
          rgba="0.2 0.2 0.2 1" />
      </material>
    </visual>
    <collision>
      <origin
        xyz="0 0 0"
        rpy="0 0 0" />
      <geometry>
        <mesh
          filename="package://bi_urdf/meshes/bat_Link.STL" />
      </geometry>
    </collision>
  </link>
  <joint
    name="bat"
    type="continuous">
    <origin
      xyz="-0.0416148109842793 0 -0.179925"
      rpy="0 0 0" />
    <parent
      link="base_link" />
    <child
      link="bat_Link" />
    <axis
      xyz="0 1 0" />
  </joint>
  <link
    name="r_Link">
    <inertial>
      <origin
        xyz="-0.02073 0.00000 0.00000"
        rpy="0 0 0" />
      <mass
        value="0.536" />
      <inertia
        ixx="0.00055434936"
        ixy="-0.00000001582"
        ixz="0.00000000503"
        iyy="0.00056855215"
        iyz="-0.00000000650"
        izz="0.00055851307"/>
    </inertial>
    <visual>
      <origin
        xyz="0 0 0"
        rpy="0 0 0" />
      <geometry>
        <mesh
          filename="package://bi_urdf/meshes/r_Link.STL" />
      </geometry>
      <material
        name="">
        <color
          rgba="1 1 0 1" />
      </material>
    </visual>
    <collision>
      <origin
        xyz="0 0 0"
        rpy="0 0 0" />
      <geometry>
        <mesh
          filename="package://bi_urdf/meshes/r_Link.STL" />
      </geometry>
    </collision>
  </link>
  <joint
    name="r"
    type="continuous">
    <origin
      xyz="-0.0535148109842786 -0.0562500000000304 -0.0547752717334899"
      rpy="0 0 0" />
    <parent
      link="base_link" />
    <child
      link="r_Link" />
    <axis
      xyz="1 0 0" />
  </joint>
  <link
    name="rr_Link">
    <inertial>
      <origin
        xyz="0.04914 0.00083 0.00000"
        rpy="0 0 0" />
      <mass
        value="0.573" />
      <inertia
        ixx="0.00035721873"
        ixy="0.00002268056"
        ixz="-0.00000005422"
        iyy="0.00204430103"
        iyz="-0.00000000125"
        izz="0.00181053200" />
    </inertial>
    <visual>
      <origin
        xyz="0 0 0"
        rpy="0 0 0" />
      <geometry>
        <mesh
          filename="package://bi_urdf/meshes/rr_Link.STL" />
      </geometry>
      <material
        name="">
        <color
          rgba="0 1 0 1" />
      </material>
    </visual>
    <collision>
      <origin
        xyz="0 0 0"
        rpy="0 0 0" />
      <geometry>
        <mesh
          filename="package://bi_urdf/meshes/rr_Link.STL" />
      </geometry>
    </collision>
  </link>
  <joint
    name="rr"
    type="continuous">
    <origin
      xyz="0 0 0"
      rpy="0 0 0" />
    <parent
      link="r_Link" />
    <child
      link="rr_Link" />
    <axis
      xyz="1 0 0" />
  </joint>
  <link
    name="rrr_Link">
    <inertial>
      <origin
        xyz="0.00003 -0.03730 0.00006"
        rpy="0 0 0" />
      <mass
        value="0.614" />
      <inertia
        ixx="0.00131289621"
        ixy="-0.00000028386"
        ixz="-0.00000248157"
        iyy="0.00065691561"
        iyz="-0.00000428299"
        izz="0.00133828329"/>
    </inertial>
    <visual>
      <origin
        xyz="0 0 0"
        rpy="0 0 0" />
      <geometry>
        <mesh
          filename="package://bi_urdf/meshes/rrr_Link.STL" />
      </geometry>
      <material
        name="">
        <color
          rgba="0 1 1 1" />
      </material>
    </visual>
    <collision>
      <origin
        xyz="0 0 0"
        rpy="0 0 0" />
      <geometry>
        <mesh
          filename="package://bi_urdf/meshes/rrr_Link.STL" />
      </geometry>
    </collision>
  </link>
  <joint
    name="rrr"
    type="continuous">
    <origin
      xyz="0.0532497748906444 -0.0144424855132765 0"
      rpy="0 0 0" />
    <parent
      link="rr_Link" />
    <child
      link="rrr_Link" />
    <axis
      xyz="0 1 0" />
  </joint>
  <link
    name="ru_Link">
    <inertial>
      <origin
        xyz="-0.00005 -0.01317 -0.06660"
        rpy="0 0 0" />
      <mass
        value="0.509" />
      <inertia
        ixx="0.00525901222"
        ixy="-0.00000006948"
        ixz="0.00000342732"
        iyy="0.00534816854"
        iyz="0.00045156221"
        izz="0.00037880824" />
    </inertial>
    <visual>
      <origin
        xyz="0 0 0"
        rpy="0 0 0" />
      <geometry>
        <mesh
          filename="package://bi_urdf/meshes/ru_Link.STL" />
      </geometry>
      <material
        name="">
        <color
          rgba="0 0 1 1" />
      </material>
    </visual>
    <collision>
      <origin
        xyz="0 0 0"
        rpy="0 0 0" />
      <geometry>
        <mesh
          filename="package://bi_urdf/meshes/ru_Link.STL" />
      </geometry>
    </collision>
  </link>
  <joint
    name="ru"
    type="continuous">
    <origin
      xyz="0 -0.0577075781855466 0"
      rpy="0 0 0" />
    <parent
      link="rrr_Link" />
    <child
      link="ru_Link" />
    <axis
      xyz="0 1 0" />
  </joint>
  <link
    name="rd_Link">
    <inertial>
      <origin
        xyz="0.00002 -0.02119 -0.15275"
        rpy="0 0 0" />
      <mass
        value="0.555" />
      <inertia
        ixx="0.07912920088"
        ixy="-0.00000017460"
        ixz="-0.00000272469"
        iyy="0.07892173375"
        iyz="0.00455705638"
        izz="0.00047477095" />
    </inertial>
    <visual>
      <origin
        xyz="0 0 0"
        rpy="0 0 0" />
      <geometry>
        <mesh
          filename="package://bi_urdf/meshes/rd_Link.STL" />
      </geometry>
      <material
        name="">
        <color
          rgba="0.792156862745098 0.819607843137255 0.933333333333333 1" />
      </material>
    </visual>
    <collision>
      <origin
        xyz="0 0 0"
        rpy="0 0 0" />
      <geometry>
        <mesh
          filename="package://bi_urdf/meshes/rd_Link.STL" />
      </geometry>
    </collision>
  </link>
  <joint
    name="rd"
    type="continuous">
    <origin
      xyz="0 0 -0.214999999999999"
      rpy="0 0 0" />
    <parent
      link="ru_Link" />
    <child
      link="rd_Link" />
    <axis
      xyz="0 1 0" />
  </joint>
  <link
    name="rw_Link">
    <inertial>
      <origin
        xyz="0.00000 -0.01520 0.00000"
        rpy="0 0 0" />
      <mass
        value="0.280" />
      <inertia
        ixx="0.00052305084"
        ixy="0.00000000000"
        ixz="-0.00000035000"
        iyy="0.00088385874"
        iyz="-0.00000014000"
        izz="0.00052304732" />
    </inertial>
    <visual>
      <origin
        xyz="0 0 0"
        rpy="0 0 0" />
      <geometry>
        <mesh
          filename="package://bi_urdf/meshes/rw_Link.STL" />
      </geometry>
      <material
        name="">
        <color
          rgba="0.2 0.2 0.2 1" />
      </material>
    </visual>
    <collision>
      <origin
        xyz="0 0 0"
        rpy="0 0 0" />
      <geometry>
        <mesh
          filename="package://bi_urdf/meshes/rw_Link.STL" />
      </geometry>
    </collision>
  </link>
  <joint
    name="rw"
    type="continuous">
    <origin
      xyz="0 -0.0286806801421281 -0.215"
      rpy="0 0 0" />
    <parent
      link="rd_Link" />
    <child
      link="rw_Link" />
    <axis
      xyz="0 1 0" />
  </joint>
  <link
    name="l_Link">
    <inertial>
      <origin
        xyz="-0.02073 0.00000 0.00000"
        rpy="0 0 0" />
      <mass
        value="0.536" />
      <inertia
        ixx="0.00055434856"
        ixy="0.00000001553"
        ixz="0.00000000306"
        iyy="0.00056854986"
        iyz="0.00000001264"
        izz="0.00055851452" />
    </inertial>
    <visual>
      <origin
        xyz="0 0 0"
        rpy="0 0 0" />
      <geometry>
        <mesh
          filename="package://bi_urdf/meshes/l_Link.STL" />
      </geometry>
      <material
        name="">
        <color
          rgba="1 1 0 1" />
      </material>
    </visual>
    <collision>
      <origin
        xyz="0 0 0"
        rpy="0 0 0" />
      <geometry>
        <mesh
          filename="package://bi_urdf/meshes/l_Link.STL" />
      </geometry>
    </collision>
  </link>
  <joint
    name="l"
    type="continuous">
    <origin
      xyz="-0.0535148109842794 0.0562499999999701 -0.0547752717334901"
      rpy="0 0 0" />
    <parent
      link="base_link" />
    <child
      link="l_Link" />
    <axis
      xyz="1 0 0" />
  </joint>
  <link
    name="ll_Link">
    <inertial>
      <origin
        xyz="0.04914 -0.00083 0.00000"
        rpy="0 0 0" />
      <mass
        value="0.573" />
      <inertia
        ixx="0.00035724030"
        ixy="-0.00002267980"
        ixz="-0.00000007079"
        iyy="0.00204413821"
        iyz="-0.00000000009"
        izz="0.00181035052"/>
    </inertial>
    <visual>
      <origin
        xyz="0 0 0"
        rpy="0 0 0" />
      <geometry>
        <mesh
          filename="package://bi_urdf/meshes/ll_Link.STL" />
      </geometry>
      <material
        name="">
        <color
          rgba="0 1 0 1" />
      </material>
    </visual>
    <collision>
      <origin
        xyz="0 0 0"
        rpy="0 0 0" />
      <geometry>
        <mesh
          filename="package://bi_urdf/meshes/ll_Link.STL" />
      </geometry>
    </collision>
  </link>
  <joint
    name="ll"
    type="continuous">
    <origin
      xyz="0 0 0"
      rpy="0 0 0" />
    <parent
      link="l_Link" />
    <child
      link="ll_Link" />
    <axis
      xyz="1 0 0" />
  </joint>
  <link
    name="lll_Link">
    <inertial>
      <origin
        xyz="0.00003 0.03730 0.00006"
        rpy="0 0 0" />
      <mass
        value="0.614" />
      <inertia
        ixx="0.00131284561"
        ixy="0.00000036570"
        ixz="-0.00000255948"
        iyy="0.00065685338"
        iyz="0.00000425719"
        izz="0.00133818598"/>
    </inertial>
    <visual>
      <origin
        xyz="0 0 0"
        rpy="0 0 0" />
      <geometry>
        <mesh
          filename="package://bi_urdf/meshes/lll_Link.STL" />
      </geometry>
      <material
        name="">
        <color
          rgba="0 1 1 1" />
      </material>
    </visual>
    <collision>
      <origin
        xyz="0 0 0"
        rpy="0 0 0" />
      <geometry>
        <mesh
          filename="package://bi_urdf/meshes/lll_Link.STL" />
      </geometry>
    </collision>
  </link>
  <joint
    name="lll"
    type="continuous">
    <origin
      xyz="0.0532497748906447 0.0144424855132758 0"
      rpy="0 0 0" />
    <parent
      link="ll_Link" />
    <child
      link="lll_Link" />
    <axis
      xyz="0 1 0" />
  </joint>
  <link
    name="lu_Link">
    <inertial>
      <origin
        xyz="-0.00005 0.01317 -0.06659"
        rpy="0 0 0" />
      <mass
        value="0.509" />
      <inertia
        ixx="0.00525893053"
        ixy="0.00000006649"
        ixz="0.00000343554"
        iyy="0.00534809715"
        iyz="-0.00045155031"
        izz="0.00037881411" />
    </inertial>
    <visual>
      <origin
        xyz="0 0 0"
        rpy="0 0 0" />
      <geometry>
        <mesh
          filename="package://bi_urdf/meshes/lu_Link.STL" />
      </geometry>
      <material
        name="">
        <color
          rgba="0 0 1 1" />
      </material>
    </visual>
    <collision>
      <origin
        xyz="0 0 0"
        rpy="0 0 0" />
      <geometry>
        <mesh
          filename="package://bi_urdf/meshes/lu_Link.STL" />
      </geometry>
    </collision>
  </link>
  <joint
    name="lu"
    type="continuous">
    <origin
      xyz="0 0.0577075781855487 0"
      rpy="0 0 0" />
    <parent
      link="lll_Link" />
    <child
      link="lu_Link" />
    <axis
      xyz="0 1 0" />
  </joint>
  <link
    name="ld_Link">
    <inertial>
      <origin
        xyz="0.00002 0.02119 -0.15276"
        rpy="0 0 0" />
      <mass
        value="0.555" />
      <inertia
        ixx="0.01701980935"
        ixy="0.00000017682"
        ixz="-0.00000009639"
        iyy="0.01681236184"
        iyz="-0.00202828700"
        izz="0.00047476800" />
    </inertial>
    <visual>
      <origin
        xyz="0 0 0"
        rpy="0 0 0" />
      <geometry>
        <mesh
          filename="package://bi_urdf/meshes/ld_Link.STL" />
      </geometry>
      <material
        name="">
        <color
          rgba="0.792156862745098 0.819607843137255 0.933333333333333 1" />
      </material>
    </visual>
    <collision>
      <origin
        xyz="0 0 0"
        rpy="0 0 0" />
      <geometry>
        <mesh
          filename="package://bi_urdf/meshes/ld_Link.STL" />
      </geometry>
    </collision>
  </link>
  <joint
    name="ld"
    type="continuous">
    <origin
      xyz="0 0 -0.215"
      rpy="0 0 0" />
    <parent
      link="lu_Link" />
    <child
      link="ld_Link" />
    <axis
      xyz="0 1 0" />
  </joint>
  <link
    name="lw_Link">
    <inertial>
      <origin
        xyz="0.00000 0.01520 0.00000"
        rpy="0 0 0" />
      <mass
        value="0.280" />
      <inertia
        ixx="0.00052305061"
        ixy="0.00000000000"
        ixz="0.00000000066"
        iyy="0.00088385420"
        iyz="0.00000000014"
        izz="0.00052304301" />
    </inertial>
    <visual>
      <origin
        xyz="0 0 0"
        rpy="0 0 0" />
      <geometry>
        <mesh
          filename="package://bi_urdf/meshes/lw_Link.STL" />
      </geometry>
      <material
        name="">
        <color
          rgba="0.2 0.2 0.2 1" />
      </material>
    </visual>
    <collision>
      <origin
        xyz="0 0 0"
        rpy="0 0 0" />
      <geometry>
        <mesh
          filename="package://bi_urdf/meshes/lw_Link.STL" />
      </geometry>
    </collision>
  </link>
  <joint
    name="lw"
    type="continuous">
    <origin
      xyz="0 0.0286806801421289 -0.215"
      rpy="0 0 0" />
    <parent
      link="ld_Link" />
    <child
      link="lw_Link" />
    <axis
      xyz="0 1 0" />
  </joint>
</robot>