<?xml version="1.0" ?>
<robot name="wheel_leg_robot">

<link name="dummy_link"/> 
<link name="base_link">
  <inertial>
    <origin xyz="0.0030042421607531134 0.020651594954696453 -0.010376287201286173" rpy="0 0 0"/>
    <mass value="0.4537635442626296"/>
    <!-- <mass value="1e-6"/> -->
    <inertia ixx="0.000743" iyy="0.000826" izz="0.000951" ixy="2e-06" iyz="-2e-06" ixz="1.2e-05"/>
  </inertial>
  <visual>
    <origin xyz="0 0 0" rpy="0 0 0"/>
    <geometry>
      <mesh filename="package://wheel_leg_description/meshes/base_link.stl" scale="0.001 0.001 0.001"/>
    </geometry>
    <material name="silver"/>
  </visual>
  <collision>
    <origin xyz="0 0 0" rpy="0 0 0"/>
    <geometry>
      <mesh filename="package://wheel_leg_description/meshes/base_link.stl" scale="0.001 0.001 0.001"/>
    </geometry>
  </collision>
</link>

<link name="upperleg_right_1">
  <inertial>
    <origin xyz="0.00038488933760329365 -0.030135564221551454 -0.022778033118308384" rpy="0 0 0"/>
    <mass value="0.07171609790839704"/>
    <inertia ixx="8.8e-05" iyy="7.6e-05" izz="2.5e-05" ixy="-0.0" iyz="1.2e-05" ixz="-1e-06"/>
  </inertial>
  <visual>
    <origin xyz="-0.0125 0.036656 0.018805" rpy="0 0 0"/>
    <geometry>
      <mesh filename="package://wheel_leg_description/meshes/upperleg_right_1.stl" scale="0.001 0.001 0.001"/>
    </geometry>
    <material name="silver"/>
  </visual>
  <collision>
    <origin xyz="-0.0125 0.036656 0.018805" rpy="0 0 0"/>
    <geometry>
      <mesh filename="package://wheel_leg_description/meshes/upperleg_right_1.stl" scale="0.001 0.001 0.001"/>
    </geometry>
  </collision>
</link>

<link name="upperleg_left_1">
  <inertial>
    <origin xyz="0.00039826234580517955 0.030135750589859636 -0.02277802829217276" rpy="0 0 0"/>
    <mass value="0.07171609699428382"/>
    <inertia ixx="8.8e-05" iyy="7.6e-05" izz="2.5e-05" ixy="0.0" iyz="-1.2e-05" ixz="-1e-06"/>
  </inertial>
  <visual>
    <origin xyz="-0.012 -0.077944 0.018805" rpy="0 0 0"/>
    <geometry>
      <mesh filename="package://wheel_leg_description/meshes/upperleg_left_1.stl" scale="0.001 0.001 0.001"/>
    </geometry>
    <material name="silver"/>
  </visual>
  <collision>
    <origin xyz="-0.012 -0.077944 0.018805" rpy="0 0 0"/>
    <geometry>
      <mesh filename="package://wheel_leg_description/meshes/upperleg_left_1.stl" scale="0.001 0.001 0.001"/>
    </geometry>
  </collision>
</link>

<link name="wheel_right_1">
  <inertial>
    <origin xyz="-1.3649211969002373e-10 -0.013854808259284666 1.5383839277460787e-07" rpy="0 0 0"/>
    <!-- <mass value="0.24089528446598812"/> -->
    <mass value="1e-6"/>
    <inertia ixx="7.5e-05" iyy="0.00014" izz="7.5e-05" ixy="-0.0" iyz="-0.0" ixz="0.0"/>
  </inertial>
  <visual>
    <origin xyz="-0.0125 0.054056 0.248805" rpy="0 0 0"/>
    <geometry>
      <mesh filename="package://wheel_leg_description/meshes/wheel_right_1.stl" scale="0.001 0.001 0.001"/>
    </geometry>
    <material name="silver"/>
  </visual>
  <collision>
    <origin xyz="-0.0125 0.054056 0.248805" rpy="0 0 0"/>
    <geometry>
      <mesh filename="package://wheel_leg_description/meshes/wheel_right_1.stl" scale="0.001 0.001 0.001"/>
    </geometry>
  </collision>
</link>

<link name="wheel_left_1">
  <inertial>
    <origin xyz="-1.9509379164256435e-09 0.013854994465382062 1.525294357485052e-07" rpy="0 0 0"/>
    <!-- <mass value="0.24089528446598812"/> -->
    <mass value="1e-6"/>
    <inertia ixx="7.5e-05" iyy="0.00014" izz="7.5e-05" ixy="0.0" iyz="0.0" ixz="0.0"/>
  </inertial>
  <visual>
    <origin xyz="-0.012 -0.095344 0.248805" rpy="0 0 0"/>
    <geometry>
      <mesh filename="package://wheel_leg_description/meshes/wheel_left_1.stl" scale="0.001 0.001 0.001"/>
    </geometry>
    <material name="silver"/>
  </visual>
  <collision>
    <origin xyz="-0.012 -0.095344 0.248805" rpy="0 0 0"/>
    <geometry>
      <mesh filename="package://wheel_leg_description/meshes/wheel_left_1.stl" scale="0.001 0.001 0.001"/>
    </geometry>
  </collision>
</link>

<link name="lowerleg_right_1">
  <inertial>
    <origin xyz="0.00014757580160875208 0.01639259995127259 -0.07790981058335422" rpy="0 0 0"/>
    <mass value="0.06800786717735839"/>
    <inertia ixx="0.000109" iyy="0.000105" izz="1.3e-05" ixy="0.0" iyz="1.4e-05" ixz="-1e-06"/>
  </inertial>
  <visual>
    <origin xyz="-0.0125 0.057756 0.138805" rpy="0 0 0"/>
    <geometry>
      <mesh filename="package://wheel_leg_description/meshes/lowerleg_right_1.stl" scale="0.001 0.001 0.001"/>
    </geometry>
    <material name="silver"/>
  </visual>
  <collision>
    <origin xyz="-0.0125 0.057756 0.138805" rpy="0 0 0"/>
    <geometry>
      <mesh filename="package://wheel_leg_description/meshes/lowerleg_right_1.stl" scale="0.001 0.001 0.001"/>
    </geometry>
  </collision>
</link>

<link name="lowerleg_left_1">
  <inertial>
    <origin xyz="0.00016167310372453524 -0.016392421334813043 -0.07790986253443566" rpy="0 0 0"/>
    <mass value="0.06800779147221263"/>
    <inertia ixx="0.000109" iyy="0.000105" izz="1.3e-05" ixy="-0.0" iyz="-1.4e-05" ixz="-1e-06"/>
  </inertial>
  <visual>
    <origin xyz="-0.012 -0.099044 0.138805" rpy="0 0 0"/>
    <geometry>
      <mesh filename="package://wheel_leg_description/meshes/lowerleg_left_1.stl" scale="0.001 0.001 0.001"/>
    </geometry>
    <material name="silver"/>
  </visual>
  <collision>
    <origin xyz="-0.012 -0.099044 0.138805" rpy="0 0 0"/>
    <geometry>
      <mesh filename="package://wheel_leg_description/meshes/lowerleg_left_1.stl" scale="0.001 0.001 0.001"/>
    </geometry>
  </collision>
</link>

<joint name="dummy_joint" type="floating">
  <parent link="dummy_link"/>
  <child link="base_link"/>
  <origin xyz="0 0 0" rpy="0 0 0"/>
</joint>

<joint name="hip_joint_right" type="revolute">
  <origin xyz="0.0125 -0.036656 -0.018805" rpy="0 0 0"/>
  <parent link="base_link"/>
  <child link="upperleg_right_1"/>
  <axis xyz="0.0 -1.0 -0.0"/>
  <limit effort="150.0" lower="-3.1415" upper="3.1415" velocity="3.15"/>
</joint>

<joint name="hip_joint_left" type="revolute">
  <origin xyz="0.012 0.077944 -0.018805" rpy="0 0 0"/>
  <parent link="base_link"/>
  <child link="upperleg_left_1"/>
  <axis xyz="0.0 1.0 0.0"/>
  <limit effort="150.0" lower="-3.1415" upper="3.1415" velocity="3.15"/>
</joint>

<joint name="wheel_joint_right" type="revolute">
  <origin xyz="0.0 0.0037 -0.11" rpy="0 0 0"/>
  <parent link="lowerleg_right_1"/>
  <child link="wheel_right_1"/>
  <axis xyz="-0.0 -1.0 -0.0"/>
  <limit effort="150.0" lower="-3.1415" upper="3.1415" velocity="3.15"/>
</joint>

<joint name="wheel_joint_left" type="revolute">
  <origin xyz="0.0 -0.0037 -0.11" rpy="0 0 0"/>
  <parent link="lowerleg_left_1"/>
  <child link="wheel_left_1"/>
  <axis xyz="-0.0 1.0 0.0"/>
  <limit effort="150.0" lower="-3.1415" upper="3.1415" velocity="3.15"/>
</joint>

<joint name="knee_joint_right" type="revolute">
  <origin xyz="0.0 -0.0211 -0.12" rpy="0 0 0"/>
  <parent link="upperleg_right_1"/>
  <child link="lowerleg_right_1"/>
  <axis xyz="0.0 -1.0 -0.0"/>
  <limit effort="150.0" lower="-3.1415" upper="3.1415" velocity="3.15"/>
</joint>

<joint name="kee_joint_left" type="revolute">
  <origin xyz="0.0 0.0211 -0.12" rpy="0 0 0"/>
  <parent link="upperleg_left_1"/>
  <child link="lowerleg_left_1"/>
  <axis xyz="-0.0 1.0 0.0"/>
  <limit effort="150.0" lower="-3.1415" upper="3.1415" velocity="3.15"/>
</joint>

</robot>
