<?xml version="1.0" ?>
<!-- =================================================================================== -->
<!-- |    This document was autogenerated by xacro from base_link.xacro                | -->
<!-- |    EDITING THIS FILE BY HAND IS NOT RECOMMENDED                                 | -->
<!-- =================================================================================== -->
<robot name="base_link">
  <material name="silver">
    <color rgba="0.700 0.700 0.700 1.000"/>
  </material>
  <transmission name="Revolute 1_tran">
    <type>transmission_interface/SimpleTransmission</type>
    <joint name="Revolute 1">
      <hardwareInterface>hardware_interface/EffortJointInterface</hardwareInterface>
    </joint>
    <actuator name="Revolute 1_actr">
      <hardwareInterface>hardware_interface/EffortJointInterface</hardwareInterface>
      <mechanicalReduction>1</mechanicalReduction>
    </actuator>
  </transmission>
  <transmission name="Revolute 2_tran">
    <type>transmission_interface/SimpleTransmission</type>
    <joint name="Revolute 2">
      <hardwareInterface>hardware_interface/EffortJointInterface</hardwareInterface>
    </joint>
    <actuator name="Revolute 2_actr">
      <hardwareInterface>hardware_interface/EffortJointInterface</hardwareInterface>
      <mechanicalReduction>1</mechanicalReduction>
    </actuator>
  </transmission>
  <gazebo>
    <plugin filename="libgazebo_ros_control.so" name="control"/>
  </gazebo>
  <gazebo reference="base_link">
    <material>Gazebo/Silver</material>
    <mu1>0.2</mu1>
    <mu2>0.2</mu2>
    <selfCollide>true</selfCollide>
    <gravity>true</gravity>
  </gazebo>
  <gazebo reference="wheel_lift_v1_1">
    <material>Gazebo/Silver</material>
    <mu1>0.2</mu1>
    <mu2>0.2</mu2>
    <selfCollide>true</selfCollide>
  </gazebo>
  <gazebo reference="wheel_right_v1_1">
    <material>Gazebo/Silver</material>
    <mu1>0.2</mu1>
    <mu2>0.2</mu2>
    <selfCollide>true</selfCollide>
  </gazebo>
  <link name="dummy_link"/>  
  <link name="base_link">
    <inertial>
      <origin rpy="0 0 0" xyz="-0.004941877527569569 -0.05029608302029057 -0.030030961139294373"/>
      <!-- <mass value="4.632301947684194"/> -->
      <mass value="1.3096"/>
      <inertia ixx="0.010338" ixy="2e-06" ixz="-1.2e-05" iyy="0.021048" iyz="0.000311" izz="0.025477"/>
    </inertial>
    <visual>
      <origin rpy="0 0 0" xyz="0 0 0"/>
      <geometry>
        <mesh filename="package://base_link_description/meshes/base_link.stl" scale="0.001 0.001 0.001"/>
      </geometry>
      <material name="silver"/>
    </visual>
    <collision>
      <origin rpy="0 0 0" xyz="0 0 0"/>
      <geometry>
        <mesh filename="package://base_link_description/meshes/base_link.stl" scale="0.001 0.001 0.001"/>
      </geometry>
    </collision>
  </link>
  <link name="wheel_lift_v1_1">
    <inertial>
      <origin rpy="0 0 0" xyz="-0.010393334643797283 -4.598582726417222e-07 4.579328673204319e-08"/>
      <!-- <mass value="0.3890337211730212"/> -->
      <mass value="1e-6"/>
      <inertia ixx="0.000176" ixy="0.0" ixz="-0.0" iyy="0.0001" iyz="-0.0" izz="0.0001"/>
    </inertial>
    <visual>
      <origin rpy="0 0 0" xyz="0.08945 0.052524 0.094931"/>
      <geometry>
        <mesh filename="package://base_link_description/meshes/wheel_lift_v1_1.stl" scale="0.001 0.001 0.001"/>
      </geometry>
      <material name="silver"/>
    </visual>
    <collision>
      <origin rpy="0 0 0" xyz="0.08945 0.052524 0.094931"/>
      <geometry>
        <mesh filename="package://base_link_description/meshes/wheel_lift_v1_1.stl" scale="0.001 0.001 0.001"/>
      </geometry>
    </collision>
  </link>
  <link name="wheel_right_v1_1">
    <inertial>
      <origin rpy="0 0 0" xyz="0.010393334643797672 -4.5985860484820673e-07 4.579342778587847e-08"/>
      <!-- <mass value="0.3890337211730212"/> -->
      <mass value="1e-6"/>
      <inertia ixx="0.000176" ixy="0.0" ixz="-0.0" iyy="0.0001" iyz="0.0" izz="0.0001"/>
    </inertial>
    <visual>
      <origin rpy="0 0 0" xyz="-0.07945 0.052524 0.094931"/>
      <geometry>
        <mesh filename="package://base_link_description/meshes/wheel_right_v1_1.stl" scale="0.001 0.001 0.001"/>
      </geometry>
      <material name="silver"/>
    </visual>
    <collision>
      <origin rpy="0 0 0" xyz="-0.07945 0.052524 0.094931"/>
      <geometry>
        <mesh filename="package://base_link_description/meshes/wheel_right_v1_1.stl" scale="0.001 0.001 0.001"/>
      </geometry>
    </collision>
  </link>
  <joint name="dummy_joint" type="floating">
    <parent link="dummy_link"/>
    <child link="base_link"/>
    <origin xyz="0 0 0" rpy="0 0 0"/>
  </joint>
  <joint name="Revolute 1" type="revolute">
    <origin rpy="0 0 0" xyz="-0.08945 -0.052524 -0.094931"/>
    <parent link="base_link"/>
    <child link="wheel_lift_v1_1"/>
    <axis xyz="1.0 -0.0 0.0"/>
    <limit effort="150.0" lower="-3.1415" upper="3.1415" velocity="3.15"/>
  </joint>
  <joint name="Revolute 2" type="revolute">
    <origin rpy="0 0 0" xyz="0.07945 -0.052524 -0.094931"/>
    <parent link="base_link"/>
    <child link="wheel_right_v1_1"/>
    <axis xyz="1.0 0.0 -0.0"/>
    <limit effort="150.0" lower="-3.1415" upper="3.1415" velocity="3.15"/>
  </joint>
</robot>
